Workbook
Name C_DiasSem: Cadastro!$K$4:$K$200
Name C_Nome: Cadastro!$B$4:$B$200
Name C_RG: Cadastro!$A$4:$A$200
Name C_Situacao: Cadastro!$C$4:$C$200
Name CP_Aprov: Compensacoes!$F$4:$F$999
Name CP_ChaveFalta: Compensacoes!$N$4:$N$999
Name CP_ChaveQuem: Compensacoes!$M$4:$M$999
Name CP_Data: Compensacoes!$A$4:$A$999
Name CP_DataFalta: Compensacoes!$E$4:$E$999
Name CP_Falta: Compensacoes!$D$4:$D$999
Name CP_Horas: Compensacoes!$C$4:$C$999
Name CP_Quem: Compensacoes!$B$4:$B$999
Name CP_Situacao: Compensacoes!$L$4:$L$999
Name F_Chave: Tabelas!$J$15:$J$54
Name F_Funcao: Tabelas!$E$15:$E$54
Name F_Ini: Tabelas!$F$15:$F$54
Name F_Valor: Tabelas!$G$15:$G$54
Name H_100: Lanc_HE!$X$4:$X$1000
Name H_50: Lanc_HE!$W$4:$W$1000
Name H_Alerta: Lanc_HE!$AB$4:$AB$1000
Name H_Area: Lanc_HE!$AA$4:$AA$1000
Name H_EI: Lanc_HE!$Z$4:$Z$1000
Name H_Equipe: Lanc_HE!$P$4:$P$1000
Name H_Funcao: Lanc_HE!$Q$4:$Q$1000
Name H_Liq: Lanc_HE!$V$4:$V$1000
Name H_Mes: Lanc_HE!$N$4:$N$1000
Name H_Nome: Lanc_HE!$B$4:$B$1000
Name H_Valor: Lanc_HE!$Y$4:$Y$1000
Name L_Alerta: Lancamentos!$AH$4:$AH$3489
Name L_Ausencia: Lancamentos!$W$4:$W$3489
Name L_Bruto: Lancamentos!$Y$4:$Y$3489
Name L_Categoria: Lancamentos!$AF$4:$AF$3489
Name L_ChaveCob: Lancamentos!$AQ$4:$AQ$3489
Name L_ChavePD: Lancamentos!$AP$4:$AP$3489
Name L_Compensado: Lancamentos!$AA$4:$AA$3489
Name L_Contrato: Lancamentos!$Q$4:$Q$3489
Name L_Data: Lancamentos!$A$4:$A$3489
Name L_DescExtra: Lancamentos!$K$4:$K$3489
Name L_Equipe: Lancamentos!$P$4:$P$3489
Name L_Ferista: Lancamentos!$Z$4:$Z$3489
Name L_Funcao: Lancamentos!$R$4:$R$3489
Name L_HorasDesc: Lancamentos!$AC$4:$AC$3489
Name L_JustExtra: Lancamentos!$L$4:$L$3489
Name L_Mes: Lancamentos!$N$4:$N$3489
Name L_Nome: Lancamentos!$B$4:$B$3489
Name L_OrdemCob: Lancamentos!$AR$4:$AR$3489
Name L_Pendente: Lancamentos!$AU$4:$AU$3489
Name L_Perdoado: Lancamentos!$AB$4:$AB$3489
Name L_RG: Lancamentos!$O$4:$O$3489
Name L_Status: Lancamentos!$C$4:$C$3489
Name L_Trab: Lancamentos!$V$4:$V$3489
Name L_Valor: Lancamentos!$AD$4:$AD$3489
Name L_ValorJust: Lancamentos!$AE$4:$AE$3489
Name lstAprov: Tabelas!$Y$4:$Y$6
Name lstAtipica: Tabelas!$W$4:$W$5
Name lstContrato: Tabelas!$AA$4:$AA$6
Name lstEquipes: Tabelas!$AC$4:$AC$23
Name lstFuncionarios: Cadastro!$B$4:$B$200
Name lstFuncoes: Tabelas!$V$4:$V$23
Name lstMeses: Resumo_Mensal!$A$5:$A$16

Sheet LEIA-ME
B1: COMO USAR — Lançamento de Horas EI36
B4: O CAMINHO DA INFORMAÇÃO
B5: Cadastro + Vigencias + Tabelas ► Lancamentos (+ Compensacoes, Lanc_HE) ► Resumo_Mensal ► Painel / Por_Colaborador
B6: Cada desconto é montado na própria linha de Lançamentos, da esquerda para a direita: Horas brutas − coberto pelo ferista − compensado (aprovado) − perdoado por acordo = Horas descontadas × Valor HH = R$. A coluna AG ("De onde vem") explica isso em texto em cada linha.
B8: CORES
B9: Amarelo / texto azul | C9: Você preenche.
B10: Azul-claro | C10: Automático (fórmula). Não digite por cima — se precisar mudar um número, use as colunas manuais amarelas.
B11: Cinza (cabeçalho) | C11: Colunas auxiliares, ficam recolhidas. Clique no [+] em cima da coluna para ver.
B12: Verde / vermelho | C12: Verde = reduziu o desconto (ferista, compensação, acordo). Vermelho = gerou desconto.
B13: Laranja | C13: Alerta: precisa da sua atenção.
B15: ABAS
B16: Painel | C16: Escolha o mês em C3. Mostra contrato, abatimento, valor final, de onde vem cada real descontado e a lista de conferência.
B17: Lancamentos | C17: Uma linha por pessoa por dia. No dia a dia preencha só A até G.
B18: Compensacoes | C18: Quem compensou a falta de quem. Só abate quando "Aprovado?" = Sim.
B19: Lanc_HE | C19: Horas extras.
B20: Resumo_Mensal | C20: 12 meses do ano. Única coisa a informar: Desconto SLA (coluna amarela).
B21: Por_Colaborador | C21: Mesmo mês do Painel, aberto por pessoa e por função.
B22: Cadastro | C22: Uma linha por pessoa (RG, nome, Ativo/Desligado).
B23: Vigencias | C23: Histórico de equipe/função/turno/tipo de contrato por data.
B24: Tabelas | C24: Parâmetros, valor do contrato por data, turnos, Valor HH por função e data, lista de Status.
B26: ROTINA DIÁRIA
B27: 1. Nova linha | C27: Data, Funcionário (lista), Status (lista).
B28: 2. Atraso / saída | C28: Cole o ponto em D no formato "HH:MM#HH:MM = H:MM". Sem ponto? Digite as horas que a pessoa ficou ausente em E.
B29: 3. Trabalhou fora da jornada | C29: Ex.: sábado de compensação de quem é ADM: digite as horas trabalhadas em F.
B30: 4. Confira | C30: Coluna AH (alerta) e o Painel de Verificação.
B32: COMPENSAÇÃO — PASSO A PASSO
B33: Exemplo: Giovani faltou em 10/09 (desconto de 9h). Ele trabalhou no sábado 12/09 para compensar.
B34: 1. Lançamentos | C34: 12/09 · Giovani · Status "Horas Compensadas" · F = 8:00 (horas trabalhadas).
B35: 2. Compensacoes | C35: Data em que trabalhou = 12/09 · Quem trabalhou = Giovani · Horas = 8:00 · Compensa a falta de = Giovani · Data da falta = 10/09 · Aprovado? = Pendente.
B36: 3. Quando aprovar | C36: Mude para "Sim". A linha da falta de 10/09 passa a mostrar "Compensado 8:00h por Giovani" e desconta só 1:00h.
B37: Colega cobrindo colega | C37: Mesma coisa, mas em "Compensa a falta de" coloque o nome de QUEM FALTOU. O Tipo vira "Colega cobriu colega". Se mudar quem compensa quem, basta editar a linha — o abatimento acompanha.
B38: Ferista | C38: Automático: no dia em que o ferista trabalha, as horas dele cobrem as faltas da equipe, começando pela MAIOR falta (empate: a que foi lançada primeiro). Para escolher manualmente, coloque "Cobertura automática do ferista?" = Não em Tabelas e registre na aba Compensações.
B39: Não abate se… | C39: Não estiver aprovado, a falta não existir nos Lançamentos ou as horas passarem da falta (o excedente é ignorado). A coluna "Situação" da aba Compensações diz qual é o caso.
B41: CASOS ESPECIAIS (colunas H–M)
B42: Posto vago | C42: Deixe Funcionário vazio e escolha a Função em H.
B43: Turno diferente no dia | C43: Escolha em I (muda a jornada só daquele dia).
B44: Situação atípica | C44: Marque J e informe horas em K (desconto extra) ou L (justificadas).
B45: Acordo com o cliente | C45: Horas perdoadas em M: saem do desconto e aparecem como "Perdoado por acordo".
B47: MUDANÇAS DE CADASTRO
B48: Pessoa nova | C48: Cadastro: RG + nome + Ativo. Vigencias: uma linha com data de início, equipe, função, turno e tipo de contrato.
...

Sheet Painel
B1: GESTÃO DE HORAS e SLA — EI36 SERRALHERIA
B3: MÊS ANALISADO ► | C3: 46266 | D3: escolha o mês na lista | K3: PAINEL DE VERIFICAÇÃO — mês selecionado
K4: O que conferir | L4: Qtde
B5: CONTRATO | D5: (−) ABATIMENTO | F5: (−) DESCONTO SLA | H5: VALOR FINAL A PAGAR | K5: Funcionário fora do Cadastro / sem vigência | L5: =COUNTIFS(L_Alerta,"CADASTRO*",L_Mes,$C$3) -> 0
B6: =IFERROR(INDEX(Resumo_Mensal!$B$5:$B$16,MATCH($C$3,Resumo_Mensal!$A$5:$A$16,0)),0) -> 138462.3 | D6: =IFERROR(INDEX(Resumo_Mensal!$H$5:$H$16,MATCH($C$3,Resumo_Mensal!$A$5:$A$16,0)),0) -> 26441.777 | F6: =IFERROR(INDEX(Resumo_Mensal!$I$5:$I$16,MATCH($C$3,Resumo_Mensal!$A$5:$A$16,0)),0) -> 11860.96 | H6: =IFERROR(INDEX(Resumo_Mensal!$J$5:$J$16,MATCH($C$3,Resumo_Mensal!$A$5:$A$16,0)),0) -> 100159.56 | K6: Lançamento duplicado (mesma pessoa/dia) | L6: =COUNTIFS(L_Alerta,"DUPLICADO*",L_Mes,$C$3) -> 0
K7: "Horas Compensadas" sem dizer de quem é a falta | L7: =COUNTIFS(L_Alerta,"VINCULAR*",L_Mes,$C$3) -> 0
B8: DE ONDE VEM O ABATIMENTO (horas lançadas − ferista − compensação − acordo = descontado) | K8: Compensação aguardando aprovação | L8: =COUNTIFS(L_Alerta,"APROVAR*",L_Mes,$C$3) -> 0
B9: Situação | C9: Horas lançadas | D9: (−) Ferista | E9: (−) Compensado | F9: (−) Perdoado | G9: Descontado (h) | H9: Valor (R$) | I9: % do total | K9: Ferista não cobriu toda a falta | L9: =COUNTIFS(L_Alerta,"FERISTA*",L_Mes,$C$3) -> 0
B10: Injustificadas (faltas + atrasos) | C10: =SUMIFS(L_Bruto,L_Mes,$C$3,L_Equipe,P_EquipePrincipal,L_Categoria,"Injustificada") -> 17.541667 | D10: =SUMIFS(L_Ferista,L_Mes,$C$3,L_Equipe,P_EquipePrincipal,L_Categoria,"Injustificada") -> 0 | E10: =SUMIFS(L_Compensado,L_Mes,$C$3,L_Equipe,P_EquipePrincipal,L_Categoria,"Injustificada") -> 2.25 | F10: =SUMIFS(L_Perdoado,L_Mes,$C$3,L_Equipe,P_EquipePrincipal,L_Categoria,"Injustificada") -> 0 | G10: =SUMIFS(L_HorasDesc,L_Mes,$C$3,L_Equipe,P_EquipePrincipal,L_Categoria,"Injustificada") -> 15.291667 | H10: =SUMIFS(L_Valor,L_Mes,$C$3,L_Equipe,P_EquipePrincipal,L_Categoria,"Injustificada") -> 20046.609 | I10: =IF($H$20=0,0,H10/$H$20) -> 0.7581415 | K10: Atraso sem ponto (descontando jornada cheia) | L10: =COUNTIFS(L_Alerta,"PONTO*",L_Mes,$C$3) -> 0
B11: Leve atraso | C11: =SUMIFS(L_Bruto,L_Mes,$C$3,L_Equipe,P_EquipePrincipal,L_Categoria,"Leve atraso") -> 0.16666667 | D11: =SUMIFS(L_Ferista,L_Mes,$C$3,L_Equipe,P_EquipePrincipal,L_Categoria,"Leve atraso") -> 0 | E11: =SUMIFS(L_Compensado,L_Mes,$C$3,L_Equipe,P_EquipePrincipal,L_Categoria,"Leve atraso") -> 0 | F11: =SUMIFS(L_Perdoado,L_Mes,$C$3,L_Equipe,P_EquipePrincipal,L_Categoria,"Leve atraso") -> 0 | G11: =SUMIFS(L_HorasDesc,L_Mes,$C$3,L_Equipe,P_EquipePrincipal,L_Categoria,"Leve atraso") -> 0.16666667 | H11: =SUMIFS(L_Valor,L_Mes,$C$3,L_Equipe,P_EquipePrincipal,L_Categoria,"Leve atraso") -> 265.64059 | I11: =IF($H$20=0,0,H11/$H$20) -> 0.010046246 | K11: Atraso > 30 min a classificar | L11: =COUNTIFS(L_Alerta,"CLASSIFICAR*",L_Mes,$C$3) -> 0
B12: Férias | C12: =SUMIFS(L_Bruto,L_Mes,$C$3,L_Equipe,P_EquipePrincipal,L_Categoria,"Férias") -> 4.4166667 | D12: =SUMIFS(L_Ferista,L_Mes,$C$3,L_Equipe,P_EquipePrincipal,L_Categoria,"Férias") -> 0 | E12: =SUMIFS(L_Compensado,L_Mes,$C$3,L_Equipe,P_EquipePrincipal,L_Categoria,"Férias") -> 0 | F12: =SUMIFS(L_Perdoado,L_Mes,$C$3,L_Equipe,P_EquipePrincipal,L_Categoria,"Férias") -> 0 | G12: =SUMIFS(L_HorasDesc,L_Mes,$C$3,L_Equipe,P_EquipePrincipal,L_Categoria,"Férias") -> 4.4166667 | H12: =SUMIFS(L_Valor,L_Mes,$C$3,L_Equipe,P_EquipePrincipal,L_Categoria,"Férias") -> 6129.5279 | I12: =IF($H$20=0,0,H12/$H$20) -> 0.23181225 | K12: Leve atraso lançado como Horas Trabalhadas | L12: =COUNTIFS(L_Alerta,"AJUSTAR*",L_Mes,$C$3) -> 1
B13: Falta de Contratação | C13: =SUMIFS(L_Bruto,L_Mes,$C$3,L_Equipe,P_EquipePrincipal,L_Categoria,"Falta de Contratação") -> 0 | D13: =SUMIFS(L_Ferista,L_Mes,$C$3,L_Equipe,P_EquipePrincipal,L_Categoria,"Falta de Contratação") -> 0 | E13: =SUMIFS(L_Compensado,L_Mes,$C$3,L_Equipe,P_EquipePrincipal,L_Categoria,"Falta de Contratação") -> 0 | F13: =SUMIFS(L_Perdoado,L_Mes,$C$3,L_Equipe,P_EquipePrincipal,L_Categoria,"Falta de Contratação") -> 0 | G13: =SUMIFS(L_HorasDesc,L_Mes,$C$3,L_Equipe,P_EquipePrincipal,L_Categoria,"Falta de Contratação") -> 0 | H13: =SUMIFS(L_Valor,L_Mes,$C$3,L_Equipe,P_EquipePrincipal,L_Categoria,"Falta de Contratação") -> 0 | I13: =IF($H$20=0,0,H13/$H$20) -> 0 | K13: Desconto extra sem observação | L13: =COUNTIFS(L_Alerta,"OBSERVAÇÃO*",L_Mes,$C$3) -> 0
B14: Falta de EPI | C14: =SUMIFS(L_Bruto,L_Mes,$C$3,L_Equipe,P_EquipePrincipal,L_Categoria,"Falta de EPI") -> 0 | D14: =SUMIFS(L_Ferista,L_Mes,$C$3,L_Equipe,P_EquipePrincipal,L_Categoria,"Falta de EPI") -> 0 | E14: =SUMIFS(L_Compensado,L_Mes,$C$3,L_Equipe,P_EquipePrincipal,L_Categoria,"Falta de EPI") -> 0 | F14: =SUMIFS(L_Perdoado,L_Mes,$C$3,L_Equipe,P_EquipePrincipal,L_Categoria,"Falta de EPI") -> 0 | G14: =SUMIFS(L_HorasDesc,L_Mes,$C$3,L_Equipe,P_EquipePrincipal,L_Categoria,"Falta de EPI") -> 0 | H14: =SUMIFS(L_Valor,L_Mes,$C$3,L_Equipe,P_EquipePrincipal,L_Categoria,"Falta de EPI") -> 0 | I14: =IF($H$20=0,0,H14/$H$20) -> 0 | K14: Horas manuais maiores que a jornada | L14: =COUNTIFS(L_Alerta,"CONFERIR*",L_Mes,$C$3) -> 0
B15: Recesso | C15: =SUMIFS(L_Bruto,L_Mes,$C$3,L_Equipe,P_EquipePrincipal,L_Categoria,"Recesso") -> 0 | D15: =SUMIFS(L_Ferista,L_Mes,$C$3,L_Equipe,P_EquipePrincipal,L_Categoria,"Recesso") -> 0 | E15: =SUMIFS(L_Compensado,L_Mes,$C$3,L_Equipe,P_EquipePrincipal,L_Categoria,"Recesso") -> 0 | F15: =SUMIFS(L_Perdoado,L_Mes,$C$3,L_Equipe,P_EquipePrincipal,L_Categoria,"Recesso") -> 0 | G15: =SUMIFS(L_HorasDesc,L_Mes,$C$3,L_Equipe,P_EquipePrincipal,L_Categoria,"Recesso") -> 0 | H15: =SUMIFS(L_Valor,L_Mes,$C$3,L_Equipe,P_EquipePrincipal,L_Categoria,"Recesso") -> 0 | I15: =IF($H$20=0,0,H15/$H$20) -> 0 | K15: HE com pendência (tratamento ou ponto) | L15: =COUNTIFS(H_Alerta,"?*",H_Mes,$C$3) -> 0
B16: Treinamento | C16: =SUMIFS(L_Bruto,L_Mes,$C$3,L_Equipe,P_EquipePrincipal,L_Categoria,"Treinamento") -> 0 | D16: =SUMIFS(L_Ferista,L_Mes,$C$3,L_Equipe,P_EquipePrincipal,L_Categoria,"Treinamento") -> 0 | E16: =SUMIFS(L_Compensado,L_Mes,$C$3,L_Equipe,P_EquipePrincipal,L_Categoria,"Treinamento") -> 0 | F16: =SUMIFS(L_Perdoado,L_Mes,$C$3,L_Equipe,P_EquipePrincipal,L_Categoria,"Treinamento") -> 0 | G16: =SUMIFS(L_HorasDesc,L_Mes,$C$3,L_Equipe,P_EquipePrincipal,L_Categoria,"Treinamento") -> 0 | H16: =SUMIFS(L_Valor,L_Mes,$C$3,L_Equipe,P_EquipePrincipal,L_Categoria,"Treinamento") -> 0 | I16: =IF($H$20=0,0,H16/$H$20) -> 0 | K16: Registros a completar na aba Compensações (todos) | L16: =COUNTIFS(CP_Situacao,"PREENCHER*")+COUNTIFS(CP_Situacao,"CONFERIR*")+COUNTIFS(CP_Situacao,"PENDENTE*") -> 12
B17: Remanejamento | C17: =SUMIFS(L_Bruto,L_Mes,$C$3,L_Equipe,P_EquipePrincipal,L_Categoria,"Remanejamento") -> 0 | D17: =SUMIFS(L_Ferista,L_Mes,$C$3,L_Equipe,P_EquipePrincipal,L_Categoria,"Remanejamento") -> 0 | E17: =SUMIFS(L_Compensado,L_Mes,$C$3,L_Equipe,P_EquipePrincipal,L_Categoria,"Remanejamento") -> 0 | F17: =SUMIFS(L_Perdoado,L_Mes,$C$3,L_Equipe,P_EquipePrincipal,L_Categoria,"Remanejamento") -> 0 | G17: =SUMIFS(L_HorasDesc,L_Mes,$C$3,L_Equipe,P_EquipePrincipal,L_Categoria,"Remanejamento") -> 0 | H17: =SUMIFS(L_Valor,L_Mes,$C$3,L_Equipe,P_EquipePrincipal,L_Categoria,"Remanejamento") -> 0 | I17: =IF($H$20=0,0,H17/$H$20) -> 0 | K17: Ativo sem lançamento há mais de 5 dias | L17: =COUNTIFS(C_DiasSem,">5") -> 0
B18: Situação atípica | C18: =SUMIFS(L_Bruto,L_Mes,$C$3,L_Equipe,P_EquipePrincipal,L_Categoria,"Situação atípica") -> 0 | D18: =SUMIFS(L_Ferista,L_Mes,$C$3,L_Equipe,P_EquipePrincipal,L_Categoria,"Situação atípica") -> 0 | E18: =SUMIFS(L_Compensado,L_Mes,$C$3,L_Equipe,P_EquipePrincipal,L_Categoria,"Situação atípica") -> 0 | F18: =SUMIFS(L_Perdoado,L_Mes,$C$3,L_Equipe,P_EquipePrincipal,L_Categoria,"Situação atípica") -> 0 | G18: =SUMIFS(L_HorasDesc,L_Mes,$C$3,L_Equipe,P_EquipePrincipal,L_Categoria,"Situação atípica") -> 0 | H18: =SUMIFS(L_Valor,L_Mes,$C$3,L_Equipe,P_EquipePrincipal,L_Categoria,"Situação atípica") -> 0 | I18: =IF($H$20=0,0,H18/$H$20) -> 0 | K18: Filtre a coluna AH de Lançamentos pelo texto do alerta para achar as linhas.
B19: Outros (manual em outros status) | C19: =SUMIFS(L_Bruto,L_Mes,$C$3,L_Equipe,P_EquipePrincipal)-SUM(C10:C18) -> 0 | D19: =SUMIFS(L_Ferista,L_Mes,$C$3,L_Equipe,P_EquipePrincipal)-SUM(D10:D18) -> 0 | E19: =SUMIFS(L_Compensado,L_Mes,$C$3,L_Equipe,P_EquipePrincipal)-SUM(E10:E18) -> 0 | F19: =SUMIFS(L_Perdoado,L_Mes,$C$3,L_Equipe,P_EquipePrincipal)-SUM(F10:F18) -> 0 | G19: =SUMIFS(L_HorasDesc,L_Mes,$C$3,L_Equipe,P_EquipePrincipal)-SUM(G10:G18) -> 0 | H19: =SUMIFS(L_Valor,L_Mes,$C$3,L_Equipe,P_EquipePrincipal)-SUM(H10:H18) -> 0 | I19: =IF($H$20=0,0,H19/$H$20) -> 0
B20: TOTAL ABATIDO | C20: =SUM(C10:C19) -> 22.125 | D20: =SUM(D10:D19) -> 0 | E20: =SUM(E10:E19) -> 2.25 | F20: =SUM(F10:F19) -> 0 | G20: =SUM(G10:G19) -> 19.875 | H20: =SUM(H10:H19) -> 26441.777 | I20: =IF($H$20=0,0,H20/$H$20) -> 1 | K20: SLA (informar)
B21: Confere com o Resumo_Mensal? | H21: =IF(ROUND(H20-D6,2)=0,"✔ confere","✘ diferença") -> ✔ confere | K21: Indicador | L21: Meta | M21: 46235 | N21: 46266 | O21: 46296 | P21: 46327 | Q21: 46357
K22: N° Atendimentos | L22: 276 | M22: 225
B23: NÃO ABATEM O CONTRATO | F23: COMPENSAÇÕES DO MÊS | K23: Backlog | L23: 321 | M23: 425
B24: Horas justificadas | C24: =IFERROR(INDEX(Resumo_Mensal!$K$5:$K$16,MATCH($C$3,Resumo_Mensal!$A$5:$A$16,0)),0) -> 8.5625 | F24: Compensado e aprovado (h) | I24: =SUMIFS(L_Compensado,L_Mes,$C$3,L_Equipe,P_EquipePrincipal) -> 2.25 | K24: Encarregado | L24: 2 | M24: 2
B25: Valor das justificadas (R$) | C25: =IFERROR(INDEX(Resumo_Mensal!$L$5:$L$16,MATCH($C$3,Resumo_Mensal!$A$5:$A$16,0)),0) -> 12001.698 | F25: Aguardando aprovação (h) | I25: =SUMIFS(L_Pendente,L_Mes,$C$3,L_Equipe,P_EquipePrincipal) -> 0 | K25: Serralheiro 1 | L25: 4 | M25: 5
F26: "Horas Compensadas" sem vínculo (linhas) | I26: =COUNTIFS(L_Alerta,"VINCULAR*",L_Mes,$C$3) -> 0 | K26: Serralheiro 2 | L26: 7 | M26: 6
F27: Registros p/ completar na aba Compensações | I27: =COUNTIFS(CP_Situacao,"PREENCHER*")+COUNTIFS(CP_Situacao,"CONFERIR*")+COUNTIFS(CP_Situacao,"PENDENTE*") -> 12
B29: FERISTA | F29: HORA EXTRA
B30: Horas trabalhadas do ferista | C30: =IFERROR(INDEX(Resumo_Mensal!$V$5:$V$16,MATCH($C$3,Resumo_Mensal!$A$5:$A$16,0)),0) -> 0 | F30: HE total (h) | I30: =IFERROR(INDEX(Resumo_Mensal!$O$5:$O$16,MATCH($C$3,Resumo_Mensal!$A$5:$A$16,0)),0)+IFERROR(INDEX(Resumo_Mensal!$P$5:$P$16,MATCH($C$3,Resumo_Mensal!$A$5:$A$16,0)),0) -> 1.3333333
B31: Horas que cobriram faltas (não abatem) | C31: =IFERROR(INDEX(Resumo_Mensal!$D$5:$D$16,MATCH($C$3,Resumo_Mensal!$A$5:$A$16,0)),0) -> 0 | F31: HE total (R$) | I31: =IFERROR(INDEX(Resumo_Mensal!$Q$5:$Q$16,MATCH($C$3,Resumo_Mensal!$A$5:$A$16,0)),0) -> 3700.847
B32: Horas do ferista sem cobertura | C32: =IFERROR(INDEX(Resumo_Mensal!$W$5:$W$16,MATCH($C$3,Resumo_Mensal!$A$5:$A$16,0)),0) -> 0 | F32: HE pagas por EI (R$) | I32: =IFERROR(INDEX(Resumo_Mensal!$R$5:$R$16,MATCH($C$3,Resumo_Mensal!$A$5:$A$16,0)),0) -> 0
B33: Cobertura automática ligada? | C33: =P_CoberturaAuto -> Sim | F33: HE pagas pela área (R$) | I33: =IFERROR(INDEX(Resumo_Mensal!$S$5:$S$16,MATCH($C$3,Resumo_Mensal!$A$5:$A$16,0)),0) -> 3700.847
B35: OPERAÇÃO | F35: SALDO
B36: Horas trabalhadas (equipe + HE) | C36: =IFERROR(INDEX(Resumo_Mensal!$N$5:$N$16,MATCH($C$3,Resumo_Mensal!$A$5:$A$16,0)),0) -> 80.020833 | F36: Saldo do mês (R$) | I36: =IFERROR(INDEX(Resumo_Mensal!$T$5:$T$16,MATCH($C$3,Resumo_Mensal!$A$5:$A$16,0)),0) -> 38302.737
B37: Horas SPOT | C37: =IFERROR(INDEX(Resumo_Mensal!$X$5:$X$16,MATCH($C$3,Resumo_Mensal!$A$5:$A$16,0)),0) -> 4.6666667 | F37: Saldo acumulado no ano (R$) | I37: =IFERROR(INDEX(Resumo_Mensal!$U$5:$U$16,MATCH($C$3,Resumo_Mensal!$A$5:$A$16,0)),0) -> 171967.24
B38: Lançamentos com desconto | C38: =IFERROR(INDEX(Resumo_Mensal!$Y$5:$Y$16,MATCH($C$3,Resumo_Mensal!$A$5:$A$16,0)),0) -> 61

Sheet Lancamentos
A1: LANÇAMENTOS DIÁRIOS — uma linha por pessoa por dia
A2: AMARELO = você preenche (A–G no dia a dia; H–M só em casos especiais). AZUL = automático, não digite por cima. Coluna AG explica de onde veio o desconto; AH mostra o que precisa de atenção. | AJ2: AUXILIARES (não editar) — clique no [+] acima para ver
A3: Data | B3: Funcionário | C3: Status | D3: Ponto (HH:MM#HH:MM = H:MM) | E3: Horas ausente (manual, se não tiver ponto) | F3: Horas trabalhadas (manual, fora da jornada) | G3: Observação | H3: Função (só posto vago) | I3: Turno no dia (se diferente) | J3: Situação atípica | K3: Desconto extra (h) | L3: Justificadas extra (h) | M3: Perdoadas por acordo (h) | N3: Mês | O3: RG | P3: Equipe | Q3: Contrato | R3: Função | S3: Turno | T3: Valor HH (R$) | U3: Jornada (h) | V3: Horas trabalhadas | W3: Horas de ausência | X3: Conta no absenteísmo? | Y3: Horas brutas a descontar | Z3: (−) Coberto pelo ferista | AA3: (−) Compensado (aprovado) | AB3: (−) Perdoado por acordo | AC3: Horas descontadas | AD3: Valor descontado (R$) | AE3: Valor justificadas (R$) | AF3: Categoria | AG3: De onde vem (rastreio) | AH3: Alerta / conferir | AJ3: vig# | AK3: Horas ponto | AL3: Modo ausência | AM3: Conta (tabela) | AN3: Trabalho? (tabela) | AO3: Déficit ponto | AP3: Chave pessoa|dia | AQ3: Chave cobertura | AR3: Ordem cobertura | AS3: Capacidade ferista | AT3: Cobertura alocada | AU3: Compensação pendente
A4: 46064 | C4: Ausências S/ Justificativa | H4: SERRALHEIRO II | N4: =IF($A4="","",DATE(YEAR($A4),MONTH($A4),1)) -> 46054 | O4: =IF(TRIM($B4)="","",IFERROR(INDEX(C_RG,MATCH(TRIM($B4),C_Nome,0)),"?")) | P4: =IF($A4="","",IF(TRIM($B4)="",P_EquipePostoVago,IF($AJ4="","",INDEX(V_Equipe,$AJ4)))) -> Serralheria | Q4: =IF($A4="","",IF(TRIM($B4)="","Posto Vago",IF($AJ4="","",INDEX(V_Contrato,$AJ4)))) -> Posto Vago | R4: =IF($A4="","",IF(TRIM($B4)="",$H4,IF($AJ4="","",INDEX(V_Funcao,$AJ4)))) -> SERRALHEIRO II | S4: =IF($A4="","",IF($I4<>"",$I4,IF(TRIM($B4)="","ADM",IF($AJ4="","",INDEX(V_Turno,$AJ4))))) -> ADM | T4: =IF(OR($A4="",$R4=""),"",IFERROR(INDEX(F_Valor,MATCH($R4&"|"&SUMPRODUCT(MAX((F_Funcao=$R4)*(F_Ini<=$A4)*F_Ini)),F_Chave,0)),"")) -> 53.080351 | U4: =IF(OR($A4="",$S4=""),0,IFERROR(INDEX(T_Horas,MATCH($S4,T_Turno,0),WEEKDAY($A4,2)),0)) -> 0.375 | V4: =IF($A4="",0,MAX(IF($F4<>"",N($F4),IF($AN4="Sim",IF($AK4<>"",$AK4,$U4),$U4-$W4))-IF($J4="Situação Atípica - Presente",N($K4),0),0)) -> 0 | W4: =IF($A4="",0,IF($E4<>"",N($E4),IF($AL4="Dia inteiro",$U4,IF($AL4="Pelo ponto",IF($AK4="",$U4,MAX($U4-$AK4,0)),IF(AND($AL4="Leve atraso",$AO4<>""),IF(AND($AO4>P_LeveMin,$AO4<=P_LeveMax),$AO4,0),0))))) -> 0.375 | X4: =IF($A4="","",IF(OR($Q4="Ferista",$Q4=""),"Não",IF(AND($AL4="Leve atraso",$W4>0,$A4>=P_InicioRegras),"Sim",IF(OR($J4<>"",$K4<>"",$L4<>""),"Não",$AM4)))) -> Sim | Y4: =IF($A4="",0,IF($Q4="Ferista",0,IF($X4="Sim",$W4,0)+N($K4))) -> 0.375 | Z4: =IF($X4="Sim",$AT4,0) -> 0 | AA4: =IF($AP4="",0,MIN(MAX($Y4-$Z4,0),SUMIFS(CP_Horas,CP_ChaveFalta,$AP4,CP_Aprov,"Sim"))) -> 0 | AB4: =IF($A4="",0,MIN(MAX($Y4-$Z4-$AA4,0),N($M4))) -> 0 | AC4: =IF($A4="",0,MAX($Y4-$Z4-$AA4-$AB4,0)) -> 0.375 | AD4: =IF(OR($AC4=0,$T4=""),0,$AC4*24*$T4) -> 477.72316 | AE4: =IF(OR($A4="",$T4=""),0,(IF($AF4="Justificada",$W4,0)+N($L4))*24*$T4) -> 0 | AF4: =IF($A4="","",IF($J4<>"","Situação atípica",IF(AND($AL4="Leve atraso",$W4>0),"Leve atraso",IFERROR(INDEX(S_Cat,MATCH($C4,S_Status,0)),"Outros")))) -> Injustificada | AG4: =IF($A4="","",TRIM(IF($Z4>0,"Ferista cobriu "&TEXT($Z4,"[h]:mm")&"h. ","")&IF($AA4>0,"Compensado "&TEXT($AA4,"[h]:mm")&"h por "&IFERROR(INDEX(CP_Quem,MATCH($AP4,CP_ChaveFalta,0)),"?")&". ","")&IF($AU4>0,"Compensação aguardando aprovação ("&TEXT($AU4,"[h]:mm")&"h). ","")&IF($AB4>0,"Perdoado por acordo "&TEXT($AB4,"[h]:mm")&"h. ","")&IF(AND($AP4<>"",COUNTIF(CP_ChaveQuem,$AP4)>0),"Horas usadas p/ compensar falta de "&INDEX(CP_Falta,MATCH($AP4,CP_ChaveQuem,0))&" de "&TEXT(INDEX(CP_DataFalta,MATCH($AP4,CP_ChaveQuem,0)),"dd/mm")&". ","")&IF(AND($Q4="Ferista",SUMIFS(L_Ferista,L_Data,$A4,L_Equipe,$P4)>0),"Como ferista, cobriu "&TEXT(SUMIFS(L_Ferista,L_Data,$A4,L_Equipe,$P4),"[h]:mm")&"h de faltas da equipe. ","")&IF($AC4>0,"DESCONTA "&TEXT($AC4,"[h]:mm")&"h ("&$AF4&").",""))) -> DESCONTA 9:00h (Injustificada). | AH4: =IF($A4="","",IF($O4="?","CADASTRO: funcionário não está no Cadastro",IF(AND($O4<>"",$AJ4=""),"CADASTRO: sem vigência (função/turno) nesta data",IF(AND($AP4<>"",COUNTIF(L_ChavePD,$AP4)>1),"DUPLICADO: mesma pessoa 2x no dia",IF($A4<P_InicioRegras,"",IF(AND($C4="Horas Compensadas",COUNTIF(CP_ChaveQuem,$AP4)=0),"VINCULAR: registrar na aba Compensações de quem é a falta",IF($AU4>0,"APROVAR: compensação pendente na aba Compensações",IF(AND($AQ4<>"",$AS4>0,$AT4<$W4,$AC4>0),"FERISTA: horas do ferista não cobriram toda a falta",IF(AND($AL4="Pelo ponto",$AK4="",$E4="",$X4="Sim"),"PONTO: sem ponto nem horas manuais — descontando jornada cheia",IF(AND($AL4="Leve atraso",$E4="",N($AO4)>P_LeveMax),"CLASSIFICAR: ponto mostra atraso > 30 min — trocar o Status",IF($AF4="Leve atraso","AJUSTAR STATUS: atraso lançado como Horas Trabalhadas",IF(AND(N($K4)>0,$G4=""),"OBSERVAÇÃO: desconto extra sem observação",IF(AND($J4<>"",N($K4)+N($L4)>$U4),"CONFERIR: horas manuais maiores que a jornada",""))))))))))))) | AJ4: =IF(OR($A4="",$O4="",$O4="?"),"",IFERROR(MATCH($O4&"|"&SUMPRODUCT(MAX((V_RG=$O4)*(V_Ini<=$A4)*V_Ini)),V_Chave,0),"")) | AK4: =IF(ISNUMBER(SEARCH(" = ",$D4)),IFERROR(TIMEVALUE(TRIM(RIGHT($D4,5))),""),"") | AL4: =IF($C4="","",IFERROR(INDEX(S_Modo,MATCH($C4,S_Status,0)),"Não")) -> Dia inteiro | AM4: =IF($C4="","",IFERROR(INDEX(S_Conta,MATCH($C4,S_Status,0)),"Não")) -> Sim | AN4: =IF($C4="","",IFERROR(INDEX(S_Trab,MATCH($C4,S_Status,0)),"Não")) -> Não | AO4: =IF(OR($A4="",$AK4=""),"",$U4-$AK4-IF($J4<>"Situação Atípica - Presente",N($K4)+N($L4),0)) | AP4: =IF(OR($A4="",TRIM($B4)=""),"",TRIM($B4)&"|"&$A4) | AQ4: =IF(AND(P_CoberturaAuto="Sim",$A4<>"",$A4>=P_InicioRegras,$Q4="Normal / Fixo",$R4<>"",ISERROR(SEARCH("ENCARREGADO",$R4)),$AM4="Sim",$W4>0),$A4&"|"&$P4,"") | AR4: =IF($AQ4="","",COUNTIFS(L_ChaveCob,$AQ4,L_Ausencia,">"&$W4)+COUNTIFS($AQ$4:$AQ4,$AQ4,$W$4:$W4,$W4)) | AS4: =IF($AQ4="",0,SUMIFS(L_Trab,L_Data,$A4,L_Equipe,$P4,L_Contrato,"Ferista",L_Status,"<>Remanejamento")) -> 0 | AT4: =IF(OR($AQ4="",$AS4=0),0,MAX(MIN($W4,$AS4-SUMIFS(L_Ausencia,L_ChaveCob,$AQ4,L_OrdemCob,"<"&$AR4)),0)) -> 0 | AU4: =IF($AP4="",0,SUMIFS(CP_Horas,CP_ChaveFalta,$AP4,CP_Aprov,"<>Sim")) -> 0
A5: 46066 | C5: Ausências S/ Justificativa | H5: SERRALHEIRO I | N5: =IF($A5="","",DATE(YEAR($A5),MONTH($A5),1)) -> 46054 | O5: =IF(TRIM($B5)="","",IFERROR(INDEX(C_RG,MATCH(TRIM($B5),C_Nome,0)),"?")) | P5: =IF($A5="","",IF(TRIM($B5)="",P_EquipePostoVago,IF($AJ5="","",INDEX(V_Equipe,$AJ5)))) -> Serralheria | Q5: =IF($A5="","",IF(TRIM($B5)="","Posto Vago",IF($AJ5="","",INDEX(V_Contrato,$AJ5)))) -> Posto Vago | R5: =IF($A5="","",IF(TRIM($B5)="",$H5,IF($AJ5="","",INDEX(V_Funcao,$AJ5)))) -> SERRALHEIRO I | S5: =IF($A5="","",IF($I5<>"",$I5,IF(TRIM($B5)="","ADM",IF($AJ5="","",INDEX(V_Turno,$AJ5))))) -> ADM | T5: =IF(OR($A5="",$R5=""),"",IFERROR(INDEX(F_Valor,MATCH($R5&"|"&SUMPRODUCT(MAX((F_Funcao=$R5)*(F_Ini<=$A5)*F_Ini)),F_Chave,0)),"")) -> 49.098892 | U5: =IF(OR($A5="",$S5=""),0,IFERROR(INDEX(T_Horas,MATCH($S5,T_Turno,0),WEEKDAY($A5,2)),0)) -> 0.33333333 | V5: =IF($A5="",0,MAX(IF($F5<>"",N($F5),IF($AN5="Sim",IF($AK5<>"",$AK5,$U5),$U5-$W5))-IF($J5="Situação Atípica - Presente",N($K5),0),0)) -> 0 | W5: =IF($A5="",0,IF($E5<>"",N($E5),IF($AL5="Dia inteiro",$U5,IF($AL5="Pelo ponto",IF($AK5="",$U5,MAX($U5-$AK5,0)),IF(AND($AL5="Leve atraso",$AO5<>""),IF(AND($AO5>P_LeveMin,$AO5<=P_LeveMax),$AO5,0),0))))) -> 0.33333333 | X5: =IF($A5="","",IF(OR($Q5="Ferista",$Q5=""),"Não",IF(AND($AL5="Leve atraso",$W5>0,$A5>=P_InicioRegras),"Sim",IF(OR($J5<>"",$K5<>"",$L5<>""),"Não",$AM5)))) -> Sim | Y5: =IF($A5="",0,IF($Q5="Ferista",0,IF($X5="Sim",$W5,0)+N($K5))) -> 0.33333333 | Z5: =IF($X5="Sim",$AT5,0) -> 0 | AA5: =IF($AP5="",0,MIN(MAX($Y5-$Z5,0),SUMIFS(CP_Horas,CP_ChaveFalta,$AP5,CP_Aprov,"Sim"))) -> 0 | AB5: =IF($A5="",0,MIN(MAX($Y5-$Z5-$AA5,0),N($M5))) -> 0 | AC5: =IF($A5="",0,MAX($Y5-$Z5-$AA5-$AB5,0)) -> 0.33333333 | AD5: =IF(OR($AC5=0,$T5=""),0,$AC5*24*$T5) -> 392.79114 | AE5: =IF(OR($A5="",$T5=""),0,(IF($AF5="Justificada",$W5,0)+N($L5))*24*$T5) -> 0 | AF5: =IF($A5="","",IF($J5<>"","Situação atípica",IF(AND($AL5="Leve atraso",$W5>0),"Leve atraso",IFERROR(INDEX(S_Cat,MATCH($C5,S_Status,0)),"Outros")))) -> Injustificada | AG5: =IF($A5="","",TRIM(IF($Z5>0,"Ferista cobriu "&TEXT($Z5,"[h]:mm")&"h. ","")&IF($AA5>0,"Compensado "&TEXT($AA5,"[h]:mm")&"h por "&IFERROR(INDEX(CP_Quem,MATCH($AP5,CP_ChaveFalta,0)),"?")&". ","")&IF($AU5>0,"Compensação aguardando aprovação ("&TEXT($AU5,"[h]:mm")&"h). ","")&IF($AB5>0,"Perdoado por acordo "&TEXT($AB5,"[h]:mm")&"h. ","")&IF(AND($AP5<>"",COUNTIF(CP_ChaveQuem,$AP5)>0),"Horas usadas p/ compensar falta de "&INDEX(CP_Falta,MATCH($AP5,CP_ChaveQuem,0))&" de "&TEXT(INDEX(CP_DataFalta,MATCH($AP5,CP_ChaveQuem,0)),"dd/mm")&". ","")&IF(AND($Q5="Ferista",SUMIFS(L_Ferista,L_Data,$A5,L_Equipe,$P5)>0),"Como ferista, cobriu "&TEXT(SUMIFS(L_Ferista,L_Data,$A5,L_Equipe,$P5),"[h]:mm")&"h de faltas da equipe. ","")&IF($AC5>0,"DESCONTA "&TEXT($AC5,"[h]:mm")&"h ("&$AF5&").",""))) -> DESCONTA 8:00h (Injustificada). | AH5: =IF($A5="","",IF($O5="?","CADASTRO: funcionário não está no Cadastro",IF(AND($O5<>"",$AJ5=""),"CADASTRO: sem vigência (função/turno) nesta data",IF(AND($AP5<>"",COUNTIF(L_ChavePD,$AP5)>1),"DUPLICADO: mesma pessoa 2x no dia",IF($A5<P_InicioRegras,"",IF(AND($C5="Horas Compensadas",COUNTIF(CP_ChaveQuem,$AP5)=0),"VINCULAR: registrar na aba Compensações de quem é a falta",IF($AU5>0,"APROVAR: compensação pendente na aba Compensações",IF(AND($AQ5<>"",$AS5>0,$AT5<$W5,$AC5>0),"FERISTA: horas do ferista não cobriram toda a falta",IF(AND($AL5="Pelo ponto",$AK5="",$E5="",$X5="Sim"),"PONTO: sem ponto nem horas manuais — descontando jornada cheia",IF(AND($AL5="Leve atraso",$E5="",N($AO5)>P_LeveMax),"CLASSIFICAR: ponto mostra atraso > 30 min — trocar o Status",IF($AF5="Leve atraso","AJUSTAR STATUS: atraso lançado como Horas Trabalhadas",IF(AND(N($K5)>0,$G5=""),"OBSERVAÇÃO: desconto extra sem observação",IF(AND($J5<>"",N($K5)+N($L5)>$U5),"CONFERIR: horas manuais maiores que a jornada",""))))))))))))) | AJ5: =IF(OR($A5="",$O5="",$O5="?"),"",IFERROR(MATCH($O5&"|"&SUMPRODUCT(MAX((V_RG=$O5)*(V_Ini<=$A5)*V_Ini)),V_Chave,0),"")) | AK5: =IF(ISNUMBER(SEARCH(" = ",$D5)),IFERROR(TIMEVALUE(TRIM(RIGHT($D5,5))),""),"") | AL5: =IF($C5="","",IFERROR(INDEX(S_Modo,MATCH($C5,S_Status,0)),"Não")) -> Dia inteiro | AM5: =IF($C5="","",IFERROR(INDEX(S_Conta,MATCH($C5,S_Status,0)),"Não")) -> Sim | AN5: =IF($C5="","",IFERROR(INDEX(S_Trab,MATCH($C5,S_Status,0)),"Não")) -> Não | AO5: =IF(OR($A5="",$AK5=""),"",$U5-$AK5-IF($J5<>"Situação Atípica - Presente",N($K5)+N($L5),0)) | AP5: =IF(OR($A5="",TRIM($B5)=""),"",TRIM($B5)&"|"&$A5) | AQ5: =IF(AND(P_CoberturaAuto="Sim",$A5<>"",$A5>=P_InicioRegras,$Q5="Normal / Fixo",$R5<>"",ISERROR(SEARCH("ENCARREGADO",$R5)),$AM5="Sim",$W5>0),$A5&"|"&$P5,"") | AR5: =IF($AQ5="","",COUNTIFS(L_ChaveCob,$AQ5,L_Ausencia,">"&$W5)+COUNTIFS($AQ$4:$AQ5,$AQ5,$W$4:$W5,$W5)) | AS5: =IF($AQ5="",0,SUMIFS(L_Trab,L_Data,$A5,L_Equipe,$P5,L_Contrato,"Ferista",L_Status,"<>Remanejamento")) -> 0 | AT5: =IF(OR($AQ5="",$AS5=0),0,MAX(MIN($W5,$AS5-SUMIFS(L_Ausencia,L_ChaveCob,$AQ5,L_OrdemCob,"<"&$AR5)),0)) -> 0 | AU5: =IF($AP5="",0,SUMIFS(CP_Horas,CP_ChaveFalta,$AP5,CP_Aprov,"<>Sim")) -> 0
A6: 46066 | C6: Ausências S/ Justificativa | H6: SERRALHEIRO I | N6: =IF($A6="","",DATE(YEAR($A6),MONTH($A6),1)) -> 46054 | O6: =IF(TRIM($B6)="","",IFERROR(INDEX(C_RG,MATCH(TRIM($B6),C_Nome,0)),"?")) | P6: =IF($A6="","",IF(TRIM($B6)="",P_EquipePostoVago,IF($AJ6="","",INDEX(V_Equipe,$AJ6)))) -> Serralheria | Q6: =IF($A6="","",IF(TRIM($B6)="","Posto Vago",IF($AJ6="","",INDEX(V_Contrato,$AJ6)))) -> Posto Vago | R6: =IF($A6="","",IF(TRIM($B6)="",$H6,IF($AJ6="","",INDEX(V_Funcao,$AJ6)))) -> SERRALHEIRO I | S6: =IF($A6="","",IF($I6<>"",$I6,IF(TRIM($B6)="","ADM",IF($AJ6="","",INDEX(V_Turno,$AJ6))))) -> ADM | T6: =IF(OR($A6="",$R6=""),"",IFERROR(INDEX(F_Valor,MATCH($R6&"|"&SUMPRODUCT(MAX((F_Funcao=$R6)*(F_Ini<=$A6)*F_Ini)),F_Chave,0)),"")) -> 49.098892 | U6: =IF(OR($A6="",$S6=""),0,IFERROR(INDEX(T_Horas,MATCH($S6,T_Turno,0),WEEKDAY($A6,2)),0)) -> 0.33333333 | V6: =IF($A6="",0,MAX(IF($F6<>"",N($F6),IF($AN6="Sim",IF($AK6<>"",$AK6,$U6),$U6-$W6))-IF($J6="Situação Atípica - Presente",N($K6),0),0)) -> 0 | W6: =IF($A6="",0,IF($E6<>"",N($E6),IF($AL6="Dia inteiro",$U6,IF($AL6="Pelo ponto",IF($AK6="",$U6,MAX($U6-$AK6,0)),IF(AND($AL6="Leve atraso",$AO6<>""),IF(AND($AO6>P_LeveMin,$AO6<=P_LeveMax),$AO6,0),0))))) -> 0.33333333 | X6: =IF($A6="","",IF(OR($Q6="Ferista",$Q6=""),"Não",IF(AND($AL6="Leve atraso",$W6>0,$A6>=P_InicioRegras),"Sim",IF(OR($J6<>"",$K6<>"",$L6<>""),"Não",$AM6)))) -> Sim | Y6: =IF($A6="",0,IF($Q6="Ferista",0,IF($X6="Sim",$W6,0)+N($K6))) -> 0.33333333 | Z6: =IF($X6="Sim",$AT6,0) -> 0 | AA6: =IF($AP6="",0,MIN(MAX($Y6-$Z6,0),SUMIFS(CP_Horas,CP_ChaveFalta,$AP6,CP_Aprov,"Sim"))) -> 0 | AB6: =IF($A6="",0,MIN(MAX($Y6-$Z6-$AA6,0),N($M6))) -> 0 | AC6: =IF($A6="",0,MAX($Y6-$Z6-$AA6-$AB6,0)) -> 0.33333333 | AD6: =IF(OR($AC6=0,$T6=""),0,$AC6*24*$T6) -> 392.79114 | AE6: =IF(OR($A6="",$T6=""),0,(IF($AF6="Justificada",$W6,0)+N($L6))*24*$T6) -> 0 | AF6: =IF($A6="","",IF($J6<>"","Situação atípica",IF(AND($AL6="Leve atraso",$W6>0),"Leve atraso",IFERROR(INDEX(S_Cat,MATCH($C6,S_Status,0)),"Outros")))) -> Injustificada | AG6: =IF($A6="","",TRIM(IF($Z6>0,"Ferista cobriu "&TEXT($Z6,"[h]:mm")&"h. ","")&IF($AA6>0,"Compensado "&TEXT($AA6,"[h]:mm")&"h por "&IFERROR(INDEX(CP_Quem,MATCH($AP6,CP_ChaveFalta,0)),"?")&". ","")&IF($AU6>0,"Compensação aguardando aprovação ("&TEXT($AU6,"[h]:mm")&"h). ","")&IF($AB6>0,"Perdoado por acordo "&TEXT($AB6,"[h]:mm")&"h. ","")&IF(AND($AP6<>"",COUNTIF(CP_ChaveQuem,$AP6)>0),"Horas usadas p/ compensar falta de "&INDEX(CP_Falta,MATCH($AP6,CP_ChaveQuem,0))&" de "&TEXT(INDEX(CP_DataFalta,MATCH($AP6,CP_ChaveQuem,0)),"dd/mm")&". ","")&IF(AND($Q6="Ferista",SUMIFS(L_Ferista,L_Data,$A6,L_Equipe,$P6)>0),"Como ferista, cobriu "&TEXT(SUMIFS(L_Ferista,L_Data,$A6,L_Equipe,$P6),"[h]:mm")&"h de faltas da equipe. ","")&IF($AC6>0,"DESCONTA "&TEXT($AC6,"[h]:mm")&"h ("&$AF6&").",""))) -> DESCONTA 8:00h (Injustificada). | AH6: =IF($A6="","",IF($O6="?","CADASTRO: funcionário não está no Cadastro",IF(AND($O6<>"",$AJ6=""),"CADASTRO: sem vigência (função/turno) nesta data",IF(AND($AP6<>"",COUNTIF(L_ChavePD,$AP6)>1),"DUPLICADO: mesma pessoa 2x no dia",IF($A6<P_InicioRegras,"",IF(AND($C6="Horas Compensadas",COUNTIF(CP_ChaveQuem,$AP6)=0),"VINCULAR: registrar na aba Compensações de quem é a falta",IF($AU6>0,"APROVAR: compensação pendente na aba Compensações",IF(AND($AQ6<>"",$AS6>0,$AT6<$W6,$AC6>0),"FERISTA: horas do ferista não cobriram toda a falta",IF(AND($AL6="Pelo ponto",$AK6="",$E6="",$X6="Sim"),"PONTO: sem ponto nem horas manuais — descontando jornada cheia",IF(AND($AL6="Leve atraso",$E6="",N($AO6)>P_LeveMax),"CLASSIFICAR: ponto mostra atraso > 30 min — trocar o Status",IF($AF6="Leve atraso","AJUSTAR STATUS: atraso lançado como Horas Trabalhadas",IF(AND(N($K6)>0,$G6=""),"OBSERVAÇÃO: desconto extra sem observação",IF(AND($J6<>"",N($K6)+N($L6)>$U6),"CONFERIR: horas manuais maiores que a jornada",""))))))))))))) | AJ6: =IF(OR($A6="",$O6="",$O6="?"),"",IFERROR(MATCH($O6&"|"&SUMPRODUCT(MAX((V_RG=$O6)*(V_Ini<=$A6)*V_Ini)),V_Chave,0),"")) | AK6: =IF(ISNUMBER(SEARCH(" = ",$D6)),IFERROR(TIMEVALUE(TRIM(RIGHT($D6,5))),""),"") | AL6: =IF($C6="","",IFERROR(INDEX(S_Modo,MATCH($C6,S_Status,0)),"Não")) -> Dia inteiro | AM6: =IF($C6="","",IFERROR(INDEX(S_Conta,MATCH($C6,S_Status,0)),"Não")) -> Sim | AN6: =IF($C6="","",IFERROR(INDEX(S_Trab,MATCH($C6,S_Status,0)),"Não")) -> Não | AO6: =IF(OR($A6="",$AK6=""),"",$U6-$AK6-IF($J6<>"Situação Atípica - Presente",N($K6)+N($L6),0)) | AP6: =IF(OR($A6="",TRIM($B6)=""),"",TRIM($B6)&"|"&$A6) | AQ6: =IF(AND(P_CoberturaAuto="Sim",$A6<>"",$A6>=P_InicioRegras,$Q6="Normal / Fixo",$R6<>"",ISERROR(SEARCH("ENCARREGADO",$R6)),$AM6="Sim",$W6>0),$A6&"|"&$P6,"") | AR6: =IF($AQ6="","",COUNTIFS(L_ChaveCob,$AQ6,L_Ausencia,">"&$W6)+COUNTIFS($AQ$4:$AQ6,$AQ6,$W$4:$W6,$W6)) | AS6: =IF($AQ6="",0,SUMIFS(L_Trab,L_Data,$A6,L_Equipe,$P6,L_Contrato,"Ferista",L_Status,"<>Remanejamento")) -> 0 | AT6: =IF(OR($AQ6="",$AS6=0),0,MAX(MIN($W6,$AS6-SUMIFS(L_Ausencia,L_ChaveCob,$AQ6,L_OrdemCob,"<"&$AR6)),0)) -> 0 | AU6: =IF($AP6="",0,SUMIFS(CP_Horas,CP_ChaveFalta,$AP6,CP_Aprov,"<>Sim")) -> 0
A7: 46067 | C7: Horas Compensadas | H7: SERRALHEIRO I | N7: =IF($A7="","",DATE(YEAR($A7),MONTH($A7),1)) -> 46054 | O7: =IF(TRIM($B7)="","",IFERROR(INDEX(C_RG,MATCH(TRIM($B7),C_Nome,0)),"?")) | P7: =IF($A7="","",IF(TRIM($B7)="",P_EquipePostoVago,IF($AJ7="","",INDEX(V_Equipe,$AJ7)))) -> Serralheria | Q7: =IF($A7="","",IF(TRIM($B7)="","Posto Vago",IF($AJ7="","",INDEX(V_Contrato,$AJ7)))) -> Posto Vago | R7: =IF($A7="","",IF(TRIM($B7)="",$H7,IF($AJ7="","",INDEX(V_Funcao,$AJ7)))) -> SERRALHEIRO I | S7: =IF($A7="","",IF($I7<>"",$I7,IF(TRIM($B7)="","ADM",IF($AJ7="","",INDEX(V_Turno,$AJ7))))) -> ADM | T7: =IF(OR($A7="",$R7=""),"",IFERROR(INDEX(F_Valor,MATCH($R7&"|"&SUMPRODUCT(MAX((F_Funcao=$R7)*(F_Ini<=$A7)*F_Ini)),F_Chave,0)),"")) -> 49.098892 | U7: =IF(OR($A7="",$S7=""),0,IFERROR(INDEX(T_Horas,MATCH($S7,T_Turno,0),WEEKDAY($A7,2)),0)) -> 0 | V7: =IF($A7="",0,MAX(IF($F7<>"",N($F7),IF($AN7="Sim",IF($AK7<>"",$AK7,$U7),$U7-$W7))-IF($J7="Situação Atípica - Presente",N($K7),0),0)) -> 0 | W7: =IF($A7="",0,IF($E7<>"",N($E7),IF($AL7="Dia inteiro",$U7,IF($AL7="Pelo ponto",IF($AK7="",$U7,MAX($U7-$AK7,0)),IF(AND($AL7="Leve atraso",$AO7<>""),IF(AND($AO7>P_LeveMin,$AO7<=P_LeveMax),$AO7,0),0))))) -> 0 | X7: =IF($A7="","",IF(OR($Q7="Ferista",$Q7=""),"Não",IF(AND($AL7="Leve atraso",$W7>0,$A7>=P_InicioRegras),"Sim",IF(OR($J7<>"",$K7<>"",$L7<>""),"Não",$AM7)))) -> Não | Y7: =IF($A7="",0,IF($Q7="Ferista",0,IF($X7="Sim",$W7,0)+N($K7))) -> 0 | Z7: =IF($X7="Sim",$AT7,0) -> 0 | AA7: =IF($AP7="",0,MIN(MAX($Y7-$Z7,0),SUMIFS(CP_Horas,CP_ChaveFalta,$AP7,CP_Aprov,"Sim"))) -> 0 | AB7: =IF($A7="",0,MIN(MAX($Y7-$Z7-$AA7,0),N($M7))) -> 0 | AC7: =IF($A7="",0,MAX($Y7-$Z7-$AA7-$AB7,0)) -> 0 | AD7: =IF(OR($AC7=0,$T7=""),0,$AC7*24*$T7) -> 0 | AE7: =IF(OR($A7="",$T7=""),0,(IF($AF7="Justificada",$W7,0)+N($L7))*24*$T7) -> 0 | AF7: =IF($A7="","",IF($J7<>"","Situação atípica",IF(AND($AL7="Leve atraso",$W7>0),"Leve atraso",IFERROR(INDEX(S_Cat,MATCH($C7,S_Status,0)),"Outros")))) -> Compensação | AG7: =IF($A7="","",TRIM(IF($Z7>0,"Ferista cobriu "&TEXT($Z7,"[h]:mm")&"h. ","")&IF($AA7>0,"Compensado "&TEXT($AA7,"[h]:mm")&"h por "&IFERROR(INDEX(CP_Quem,MATCH($AP7,CP_ChaveFalta,0)),"?")&". ","")&IF($AU7>0,"Compensação aguardando aprovação ("&TEXT($AU7,"[h]:mm")&"h). ","")&IF($AB7>0,"Perdoado por acordo "&TEXT($AB7,"[h]:mm")&"h. ","")&IF(AND($AP7<>"",COUNTIF(CP_ChaveQuem,$AP7)>0),"Horas usadas p/ compensar falta de "&INDEX(CP_Falta,MATCH($AP7,CP_ChaveQuem,0))&" de "&TEXT(INDEX(CP_DataFalta,MATCH($AP7,CP_ChaveQuem,0)),"dd/mm")&". ","")&IF(AND($Q7="Ferista",SUMIFS(L_Ferista,L_Data,$A7,L_Equipe,$P7)>0),"Como ferista, cobriu "&TEXT(SUMIFS(L_Ferista,L_Data,$A7,L_Equipe,$P7),"[h]:mm")&"h de faltas da equipe. ","")&IF($AC7>0,"DESCONTA "&TEXT($AC7,"[h]:mm")&"h ("&$AF7&").",""))) | AH7: =IF($A7="","",IF($O7="?","CADASTRO: funcionário não está no Cadastro",IF(AND($O7<>"",$AJ7=""),"CADASTRO: sem vigência (função/turno) nesta data",IF(AND($AP7<>"",COUNTIF(L_ChavePD,$AP7)>1),"DUPLICADO: mesma pessoa 2x no dia",IF($A7<P_InicioRegras,"",IF(AND($C7="Horas Compensadas",COUNTIF(CP_ChaveQuem,$AP7)=0),"VINCULAR: registrar na aba Compensações de quem é a falta",IF($AU7>0,"APROVAR: compensação pendente na aba Compensações",IF(AND($AQ7<>"",$AS7>0,$AT7<$W7,$AC7>0),"FERISTA: horas do ferista não cobriram toda a falta",IF(AND($AL7="Pelo ponto",$AK7="",$E7="",$X7="Sim"),"PONTO: sem ponto nem horas manuais — descontando jornada cheia",IF(AND($AL7="Leve atraso",$E7="",N($AO7)>P_LeveMax),"CLASSIFICAR: ponto mostra atraso > 30 min — trocar o Status",IF($AF7="Leve atraso","AJUSTAR STATUS: atraso lançado como Horas Trabalhadas",IF(AND(N($K7)>0,$G7=""),"OBSERVAÇÃO: desconto extra sem observação",IF(AND($J7<>"",N($K7)+N($L7)>$U7),"CONFERIR: horas manuais maiores que a jornada",""))))))))))))) | AJ7: =IF(OR($A7="",$O7="",$O7="?"),"",IFERROR(MATCH($O7&"|"&SUMPRODUCT(MAX((V_RG=$O7)*(V_Ini<=$A7)*V_Ini)),V_Chave,0),"")) | AK7: =IF(ISNUMBER(SEARCH(" = ",$D7)),IFERROR(TIMEVALUE(TRIM(RIGHT($D7,5))),""),"") | AL7: =IF($C7="","",IFERROR(INDEX(S_Modo,MATCH($C7,S_Status,0)),"Não")) -> Não | AM7: =IF($C7="","",IFERROR(INDEX(S_Conta,MATCH($C7,S_Status,0)),"Não")) -> Não | AN7: =IF($C7="","",IFERROR(INDEX(S_Trab,MATCH($C7,S_Status,0)),"Não")) -> Sim | AO7: =IF(OR($A7="",$AK7=""),"",$U7-$AK7-IF($J7<>"Situação Atípica - Presente",N($K7)+N($L7),0)) | AP7: =IF(OR($A7="",TRIM($B7)=""),"",TRIM($B7)&"|"&$A7) | AQ7: =IF(AND(P_CoberturaAuto="Sim",$A7<>"",$A7>=P_InicioRegras,$Q7="Normal / Fixo",$R7<>"",ISERROR(SEARCH("ENCARREGADO",$R7)),$AM7="Sim",$W7>0),$A7&"|"&$P7,"") | AR7: =IF($AQ7="","",COUNTIFS(L_ChaveCob,$AQ7,L_Ausencia,">"&$W7)+COUNTIFS($AQ$4:$AQ7,$AQ7,$W$4:$W7,$W7)) | AS7: =IF($AQ7="",0,SUMIFS(L_Trab,L_Data,$A7,L_Equipe,$P7,L_Contrato,"Ferista",L_Status,"<>Remanejamento")) -> 0 | AT7: =IF(OR($AQ7="",$AS7=0),0,MAX(MIN($W7,$AS7-SUMIFS(L_Ausencia,L_ChaveCob,$AQ7,L_OrdemCob,"<"&$AR7)),0)) -> 0 | AU7: =IF($AP7="",0,SUMIFS(CP_Horas,CP_ChaveFalta,$AP7,CP_Aprov,"<>Sim")) -> 0
A8: 46067 | C8: Horas Compensadas | H8: SERRALHEIRO II | N8: =IF($A8="","",DATE(YEAR($A8),MONTH($A8),1)) -> 46054 | O8: =IF(TRIM($B8)="","",IFERROR(INDEX(C_RG,MATCH(TRIM($B8),C_Nome,0)),"?")) | P8: =IF($A8="","",IF(TRIM($B8)="",P_EquipePostoVago,IF($AJ8="","",INDEX(V_Equipe,$AJ8)))) -> Serralheria | Q8: =IF($A8="","",IF(TRIM($B8)="","Posto Vago",IF($AJ8="","",INDEX(V_Contrato,$AJ8)))) -> Posto Vago | R8: =IF($A8="","",IF(TRIM($B8)="",$H8,IF($AJ8="","",INDEX(V_Funcao,$AJ8)))) -> SERRALHEIRO II | S8: =IF($A8="","",IF($I8<>"",$I8,IF(TRIM($B8)="","ADM",IF($AJ8="","",INDEX(V_Turno,$AJ8))))) -> ADM | T8: =IF(OR($A8="",$R8=""),"",IFERROR(INDEX(F_Valor,MATCH($R8&"|"&SUMPRODUCT(MAX((F_Funcao=$R8)*(F_Ini<=$A8)*F_Ini)),F_Chave,0)),"")) -> 53.080351 | U8: =IF(OR($A8="",$S8=""),0,IFERROR(INDEX(T_Horas,MATCH($S8,T_Turno,0),WEEKDAY($A8,2)),0)) -> 0 | V8: =IF($A8="",0,MAX(IF($F8<>"",N($F8),IF($AN8="Sim",IF($AK8<>"",$AK8,$U8),$U8-$W8))-IF($J8="Situação Atípica - Presente",N($K8),0),0)) -> 0 | W8: =IF($A8="",0,IF($E8<>"",N($E8),IF($AL8="Dia inteiro",$U8,IF($AL8="Pelo ponto",IF($AK8="",$U8,MAX($U8-$AK8,0)),IF(AND($AL8="Leve atraso",$AO8<>""),IF(AND($AO8>P_LeveMin,$AO8<=P_LeveMax),$AO8,0),0))))) -> 0 | X8: =IF($A8="","",IF(OR($Q8="Ferista",$Q8=""),"Não",IF(AND($AL8="Leve atraso",$W8>0,$A8>=P_InicioRegras),"Sim",IF(OR($J8<>"",$K8<>"",$L8<>""),"Não",$AM8)))) -> Não | Y8: =IF($A8="",0,IF($Q8="Ferista",0,IF($X8="Sim",$W8,0)+N($K8))) -> 0 | Z8: =IF($X8="Sim",$AT8,0) -> 0 | AA8: =IF($AP8="",0,MIN(MAX($Y8-$Z8,0),SUMIFS(CP_Horas,CP_ChaveFalta,$AP8,CP_Aprov,"Sim"))) -> 0 | AB8: =IF($A8="",0,MIN(MAX($Y8-$Z8-$AA8,0),N($M8))) -> 0 | AC8: =IF($A8="",0,MAX($Y8-$Z8-$AA8-$AB8,0)) -> 0 | AD8: =IF(OR($AC8=0,$T8=""),0,$AC8*24*$T8) -> 0 | AE8: =IF(OR($A8="",$T8=""),0,(IF($AF8="Justificada",$W8,0)+N($L8))*24*$T8) -> 0 | AF8: =IF($A8="","",IF($J8<>"","Situação atípica",IF(AND($AL8="Leve atraso",$W8>0),"Leve atraso",IFERROR(INDEX(S_Cat,MATCH($C8,S_Status,0)),"Outros")))) -> Compensação | AG8: =IF($A8="","",TRIM(IF($Z8>0,"Ferista cobriu "&TEXT($Z8,"[h]:mm")&"h. ","")&IF($AA8>0,"Compensado "&TEXT($AA8,"[h]:mm")&"h por "&IFERROR(INDEX(CP_Quem,MATCH($AP8,CP_ChaveFalta,0)),"?")&". ","")&IF($AU8>0,"Compensação aguardando aprovação ("&TEXT($AU8,"[h]:mm")&"h). ","")&IF($AB8>0,"Perdoado por acordo "&TEXT($AB8,"[h]:mm")&"h. ","")&IF(AND($AP8<>"",COUNTIF(CP_ChaveQuem,$AP8)>0),"Horas usadas p/ compensar falta de "&INDEX(CP_Falta,MATCH($AP8,CP_ChaveQuem,0))&" de "&TEXT(INDEX(CP_DataFalta,MATCH($AP8,CP_ChaveQuem,0)),"dd/mm")&". ","")&IF(AND($Q8="Ferista",SUMIFS(L_Ferista,L_Data,$A8,L_Equipe,$P8)>0),"Como ferista, cobriu "&TEXT(SUMIFS(L_Ferista,L_Data,$A8,L_Equipe,$P8),"[h]:mm")&"h de faltas da equipe. ","")&IF($AC8>0,"DESCONTA "&TEXT($AC8,"[h]:mm")&"h ("&$AF8&").",""))) | AH8: =IF($A8="","",IF($O8="?","CADASTRO: funcionário não está no Cadastro",IF(AND($O8<>"",$AJ8=""),"CADASTRO: sem vigência (função/turno) nesta data",IF(AND($AP8<>"",COUNTIF(L_ChavePD,$AP8)>1),"DUPLICADO: mesma pessoa 2x no dia",IF($A8<P_InicioRegras,"",IF(AND($C8="Horas Compensadas",COUNTIF(CP_ChaveQuem,$AP8)=0),"VINCULAR: registrar na aba Compensações de quem é a falta",IF($AU8>0,"APROVAR: compensação pendente na aba Compensações",IF(AND($AQ8<>"",$AS8>0,$AT8<$W8,$AC8>0),"FERISTA: horas do ferista não cobriram toda a falta",IF(AND($AL8="Pelo ponto",$AK8="",$E8="",$X8="Sim"),"PONTO: sem ponto nem horas manuais — descontando jornada cheia",IF(AND($AL8="Leve atraso",$E8="",N($AO8)>P_LeveMax),"CLASSIFICAR: ponto mostra atraso > 30 min — trocar o Status",IF($AF8="Leve atraso","AJUSTAR STATUS: atraso lançado como Horas Trabalhadas",IF(AND(N($K8)>0,$G8=""),"OBSERVAÇÃO: desconto extra sem observação",IF(AND($J8<>"",N($K8)+N($L8)>$U8),"CONFERIR: horas manuais maiores que a jornada",""))))))))))))) | AJ8: =IF(OR($A8="",$O8="",$O8="?"),"",IFERROR(MATCH($O8&"|"&SUMPRODUCT(MAX((V_RG=$O8)*(V_Ini<=$A8)*V_Ini)),V_Chave,0),"")) | AK8: =IF(ISNUMBER(SEARCH(" = ",$D8)),IFERROR(TIMEVALUE(TRIM(RIGHT($D8,5))),""),"") | AL8: =IF($C8="","",IFERROR(INDEX(S_Modo,MATCH($C8,S_Status,0)),"Não")) -> Não | AM8: =IF($C8="","",IFERROR(INDEX(S_Conta,MATCH($C8,S_Status,0)),"Não")) -> Não | AN8: =IF($C8="","",IFERROR(INDEX(S_Trab,MATCH($C8,S_Status,0)),"Não")) -> Sim | AO8: =IF(OR($A8="",$AK8=""),"",$U8-$AK8-IF($J8<>"Situação Atípica - Presente",N($K8)+N($L8),0)) | AP8: =IF(OR($A8="",TRIM($B8)=""),"",TRIM($B8)&"|"&$A8) | AQ8: =IF(AND(P_CoberturaAuto="Sim",$A8<>"",$A8>=P_InicioRegras,$Q8="Normal / Fixo",$R8<>"",ISERROR(SEARCH("ENCARREGADO",$R8)),$AM8="Sim",$W8>0),$A8&"|"&$P8,"") | AR8: =IF($AQ8="","",COUNTIFS(L_ChaveCob,$AQ8,L_Ausencia,">"&$W8)+COUNTIFS($AQ$4:$AQ8,$AQ8,$W$4:$W8,$W8)) | AS8: =IF($AQ8="",0,SUMIFS(L_Trab,L_Data,$A8,L_Equipe,$P8,L_Contrato,"Ferista",L_Status,"<>Remanejamento")) -> 0 | AT8: =IF(OR($AQ8="",$AS8=0),0,MAX(MIN($W8,$AS8-SUMIFS(L_Ausencia,L_ChaveCob,$AQ8,L_OrdemCob,"<"&$AR8)),0)) -> 0 | AU8: =IF($AP8="",0,SUMIFS(CP_Horas,CP_ChaveFalta,$AP8,CP_Aprov,"<>Sim")) -> 0
A9: 46067 | C9: Horas Compensadas | G9: Abatimento de horas conforme reunião | H9: SERRALHEIRO II | N9: =IF($A9="","",DATE(YEAR($A9),MONTH($A9),1)) -> 46054 | O9: =IF(TRIM($B9)="","",IFERROR(INDEX(C_RG,MATCH(TRIM($B9),C_Nome,0)),"?")) | P9: =IF($A9="","",IF(TRIM($B9)="",P_EquipePostoVago,IF($AJ9="","",INDEX(V_Equipe,$AJ9)))) -> Serralheria | Q9: =IF($A9="","",IF(TRIM($B9)="","Posto Vago",IF($AJ9="","",INDEX(V_Contrato,$AJ9)))) -> Posto Vago | R9: =IF($A9="","",IF(TRIM($B9)="",$H9,IF($AJ9="","",INDEX(V_Funcao,$AJ9)))) -> SERRALHEIRO II | S9: =IF($A9="","",IF($I9<>"",$I9,IF(TRIM($B9)="","ADM",IF($AJ9="","",INDEX(V_Turno,$AJ9))))) -> ADM | T9: =IF(OR($A9="",$R9=""),"",IFERROR(INDEX(F_Valor,MATCH($R9&"|"&SUMPRODUCT(MAX((F_Funcao=$R9)*(F_Ini<=$A9)*F_Ini)),F_Chave,0)),"")) -> 53.080351 | U9: =IF(OR($A9="",$S9=""),0,IFERROR(INDEX(T_Horas,MATCH($S9,T_Turno,0),WEEKDAY($A9,2)),0)) -> 0 | V9: =IF($A9="",0,MAX(IF($F9<>"",N($F9),IF($AN9="Sim",IF($AK9<>"",$AK9,$U9),$U9-$W9))-IF($J9="Situação Atípica - Presente",N($K9),0),0)) -> 0 | W9: =IF($A9="",0,IF($E9<>"",N($E9),IF($AL9="Dia inteiro",$U9,IF($AL9="Pelo ponto",IF($AK9="",$U9,MAX($U9-$AK9,0)),IF(AND($AL9="Leve atraso",$AO9<>""),IF(AND($AO9>P_LeveMin,$AO9<=P_LeveMax),$AO9,0),0))))) -> 0 | X9: =IF($A9="","",IF(OR($Q9="Ferista",$Q9=""),"Não",IF(AND($AL9="Leve atraso",$W9>0,$A9>=P_InicioRegras),"Sim",IF(OR($J9<>"",$K9<>"",$L9<>""),"Não",$AM9)))) -> Não | Y9: =IF($A9="",0,IF($Q9="Ferista",0,IF($X9="Sim",$W9,0)+N($K9))) -> 0 | Z9: =IF($X9="Sim",$AT9,0) -> 0 | AA9: =IF($AP9="",0,MIN(MAX($Y9-$Z9,0),SUMIFS(CP_Horas,CP_ChaveFalta,$AP9,CP_Aprov,"Sim"))) -> 0 | AB9: =IF($A9="",0,MIN(MAX($Y9-$Z9-$AA9,0),N($M9))) -> 0 | AC9: =IF($A9="",0,MAX($Y9-$Z9-$AA9-$AB9,0)) -> 0 | AD9: =IF(OR($AC9=0,$T9=""),0,$AC9*24*$T9) -> 0 | AE9: =IF(OR($A9="",$T9=""),0,(IF($AF9="Justificada",$W9,0)+N($L9))*24*$T9) -> 0 | AF9: =IF($A9="","",IF($J9<>"","Situação atípica",IF(AND($AL9="Leve atraso",$W9>0),"Leve atraso",IFERROR(INDEX(S_Cat,MATCH($C9,S_Status,0)),"Outros")))) -> Compensação | AG9: =IF($A9="","",TRIM(IF($Z9>0,"Ferista cobriu "&TEXT($Z9,"[h]:mm")&"h. ","")&IF($AA9>0,"Compensado "&TEXT($AA9,"[h]:mm")&"h por "&IFERROR(INDEX(CP_Quem,MATCH($AP9,CP_ChaveFalta,0)),"?")&". ","")&IF($AU9>0,"Compensação aguardando aprovação ("&TEXT($AU9,"[h]:mm")&"h). ","")&IF($AB9>0,"Perdoado por acordo "&TEXT($AB9,"[h]:mm")&"h. ","")&IF(AND($AP9<>"",COUNTIF(CP_ChaveQuem,$AP9)>0),"Horas usadas p/ compensar falta de "&INDEX(CP_Falta,MATCH($AP9,CP_ChaveQuem,0))&" de "&TEXT(INDEX(CP_DataFalta,MATCH($AP9,CP_ChaveQuem,0)),"dd/mm")&". ","")&IF(AND($Q9="Ferista",SUMIFS(L_Ferista,L_Data,$A9,L_Equipe,$P9)>0),"Como ferista, cobriu "&TEXT(SUMIFS(L_Ferista,L_Data,$A9,L_Equipe,$P9),"[h]:mm")&"h de faltas da equipe. ","")&IF($AC9>0,"DESCONTA "&TEXT($AC9,"[h]:mm")&"h ("&$AF9&").",""))) | AH9: =IF($A9="","",IF($O9="?","CADASTRO: funcionário não está no Cadastro",IF(AND($O9<>"",$AJ9=""),"CADASTRO: sem vigência (função/turno) nesta data",IF(AND($AP9<>"",COUNTIF(L_ChavePD,$AP9)>1),"DUPLICADO: mesma pessoa 2x no dia",IF($A9<P_InicioRegras,"",IF(AND($C9="Horas Compensadas",COUNTIF(CP_ChaveQuem,$AP9)=0),"VINCULAR: registrar na aba Compensações de quem é a falta",IF($AU9>0,"APROVAR: compensação pendente na aba Compensações",IF(AND($AQ9<>"",$AS9>0,$AT9<$W9,$AC9>0),"FERISTA: horas do ferista não cobriram toda a falta",IF(AND($AL9="Pelo ponto",$AK9="",$E9="",$X9="Sim"),"PONTO: sem ponto nem horas manuais — descontando jornada cheia",IF(AND($AL9="Leve atraso",$E9="",N($AO9)>P_LeveMax),"CLASSIFICAR: ponto mostra atraso > 30 min — trocar o Status",IF($AF9="Leve atraso","AJUSTAR STATUS: atraso lançado como Horas Trabalhadas",IF(AND(N($K9)>0,$G9=""),"OBSERVAÇÃO: desconto extra sem observação",IF(AND($J9<>"",N($K9)+N($L9)>$U9),"CONFERIR: horas manuais maiores que a jornada",""))))))))))))) | AJ9: =IF(OR($A9="",$O9="",$O9="?"),"",IFERROR(MATCH($O9&"|"&SUMPRODUCT(MAX((V_RG=$O9)*(V_Ini<=$A9)*V_Ini)),V_Chave,0),"")) | AK9: =IF(ISNUMBER(SEARCH(" = ",$D9)),IFERROR(TIMEVALUE(TRIM(RIGHT($D9,5))),""),"") | AL9: =IF($C9="","",IFERROR(INDEX(S_Modo,MATCH($C9,S_Status,0)),"Não")) -> Não | AM9: =IF($C9="","",IFERROR(INDEX(S_Conta,MATCH($C9,S_Status,0)),"Não")) -> Não | AN9: =IF($C9="","",IFERROR(INDEX(S_Trab,MATCH($C9,S_Status,0)),"Não")) -> Sim | AO9: =IF(OR($A9="",$AK9=""),"",$U9-$AK9-IF($J9<>"Situação Atípica - Presente",N($K9)+N($L9),0)) | AP9: =IF(OR($A9="",TRIM($B9)=""),"",TRIM($B9)&"|"&$A9) | AQ9: =IF(AND(P_CoberturaAuto="Sim",$A9<>"",$A9>=P_InicioRegras,$Q9="Normal / Fixo",$R9<>"",ISERROR(SEARCH("ENCARREGADO",$R9)),$AM9="Sim",$W9>0),$A9&"|"&$P9,"") | AR9: =IF($AQ9="","",COUNTIFS(L_ChaveCob,$AQ9,L_Ausencia,">"&$W9)+COUNTIFS($AQ$4:$AQ9,$AQ9,$W$4:$W9,$W9)) | AS9: =IF($AQ9="",0,SUMIFS(L_Trab,L_Data,$A9,L_Equipe,$P9,L_Contrato,"Ferista",L_Status,"<>Remanejamento")) -> 0 | AT9: =IF(OR($AQ9="",$AS9=0),0,MAX(MIN($W9,$AS9-SUMIFS(L_Ausencia,L_ChaveCob,$AQ9,L_OrdemCob,"<"&$AR9)),0)) -> 0 | AU9: =IF($AP9="",0,SUMIFS(CP_Horas,CP_ChaveFalta,$AP9,CP_Aprov,"<>Sim")) -> 0
A10: 46069 | C10: Ausências Devido a Recesso | H10: ENCARREGADO | N10: =IF($A10="","",DATE(YEAR($A10),MONTH($A10),1)) -> 46054 | O10: =IF(TRIM($B10)="","",IFERROR(INDEX(C_RG,MATCH(TRIM($B10),C_Nome,0)),"?")) | P10: =IF($A10="","",IF(TRIM($B10)="",P_EquipePostoVago,IF($AJ10="","",INDEX(V_Equipe,$AJ10)))) -> Serralheria | Q10: =IF($A10="","",IF(TRIM($B10)="","Posto Vago",IF($AJ10="","",INDEX(V_Contrato,$AJ10)))) -> Posto Vago | R10: =IF($A10="","",IF(TRIM($B10)="",$H10,IF($AJ10="","",INDEX(V_Funcao,$AJ10)))) -> ENCARREGADO | S10: =IF($A10="","",IF($I10<>"",$I10,IF(TRIM($B10)="","ADM",IF($AJ10="","",INDEX(V_Turno,$AJ10))))) -> ADM | T10: =IF(OR($A10="",$R10=""),"",IFERROR(INDEX(F_Valor,MATCH($R10&"|"&SUMPRODUCT(MAX((F_Funcao=$R10)*(F_Ini<=$A10)*F_Ini)),F_Chave,0)),"")) -> 60.96 | U10: =IF(OR($A10="",$S10=""),0,IFERROR(INDEX(T_Horas,MATCH($S10,T_Turno,0),WEEKDAY($A10,2)),0)) -> 0.375 | V10: =IF($A10="",0,MAX(IF($F10<>"",N($F10),IF($AN10="Sim",IF($AK10<>"",$AK10,$U10),$U10-$W10))-IF($J10="Situação Atípica - Presente",N($K10),0),0)) -> 0 | W10: =IF($A10="",0,IF($E10<>"",N($E10),IF($AL10="Dia inteiro",$U10,IF($AL10="Pelo ponto",IF($AK10="",$U10,MAX($U10-$AK10,0)),IF(AND($AL10="Leve atraso",$AO10<>""),IF(AND($AO10>P_LeveMin,$AO10<=P_LeveMax),$AO10,0),0))))) -> 0.375 | X10: =IF($A10="","",IF(OR($Q10="Ferista",$Q10=""),"Não",IF(AND($AL10="Leve atraso",$W10>0,$A10>=P_InicioRegras),"Sim",IF(OR($J10<>"",$K10<>"",$L10<>""),"Não",$AM10)))) -> Sim | Y10: =IF($A10="",0,IF($Q10="Ferista",0,IF($X10="Sim",$W10,0)+N($K10))) -> 0.375 | Z10: =IF($X10="Sim",$AT10,0) -> 0 | AA10: =IF($AP10="",0,MIN(MAX($Y10-$Z10,0),SUMIFS(CP_Horas,CP_ChaveFalta,$AP10,CP_Aprov,"Sim"))) -> 0 | AB10: =IF($A10="",0,MIN(MAX($Y10-$Z10-$AA10,0),N($M10))) -> 0 | AC10: =IF($A10="",0,MAX($Y10-$Z10-$AA10-$AB10,0)) -> 0.375 | AD10: =IF(OR($AC10=0,$T10=""),0,$AC10*24*$T10) -> 548.64 | AE10: =IF(OR($A10="",$T10=""),0,(IF($AF10="Justificada",$W10,0)+N($L10))*24*$T10) -> 0 | AF10: =IF($A10="","",IF($J10<>"","Situação atípica",IF(AND($AL10="Leve atraso",$W10>0),"Leve atraso",IFERROR(INDEX(S_Cat,MATCH($C10,S_Status,0)),"Outros")))) -> Recesso | AG10: =IF($A10="","",TRIM(IF($Z10>0,"Ferista cobriu "&TEXT($Z10,"[h]:mm")&"h. ","")&IF($AA10>0,"Compensado "&TEXT($AA10,"[h]:mm")&"h por "&IFERROR(INDEX(CP_Quem,MATCH($AP10,CP_ChaveFalta,0)),"?")&". ","")&IF($AU10>0,"Compensação aguardando aprovação ("&TEXT($AU10,"[h]:mm")&"h). ","")&IF($AB10>0,"Perdoado por acordo "&TEXT($AB10,"[h]:mm")&"h. ","")&IF(AND($AP10<>"",COUNTIF(CP_ChaveQuem,$AP10)>0),"Horas usadas p/ compensar falta de "&INDEX(CP_Falta,MATCH($AP10,CP_ChaveQuem,0))&" de "&TEXT(INDEX(CP_DataFalta,MATCH($AP10,CP_ChaveQuem,0)),"dd/mm")&". ","")&IF(AND($Q10="Ferista",SUMIFS(L_Ferista,L_Data,$A10,L_Equipe,$P10)>0),"Como ferista, cobriu "&TEXT(SUMIFS(L_Ferista,L_Data,$A10,L_Equipe,$P10),"[h]:mm")&"h de faltas da equipe. ","")&IF($AC10>0,"DESCONTA "&TEXT($AC10,"[h]:mm")&"h ("&$AF10&").",""))) -> DESCONTA 9:00h (Recesso). | AH10: =IF($A10="","",IF($O10="?","CADASTRO: funcionário não está no Cadastro",IF(AND($O10<>"",$AJ10=""),"CADASTRO: sem vigência (função/turno) nesta data",IF(AND($AP10<>"",COUNTIF(L_ChavePD,$AP10)>1),"DUPLICADO: mesma pessoa 2x no dia",IF($A10<P_InicioRegras,"",IF(AND($C10="Horas Compensadas",COUNTIF(CP_ChaveQuem,$AP10)=0),"VINCULAR: registrar na aba Compensações de quem é a falta",IF($AU10>0,"APROVAR: compensação pendente na aba Compensações",IF(AND($AQ10<>"",$AS10>0,$AT10<$W10,$AC10>0),"FERISTA: horas do ferista não cobriram toda a falta",IF(AND($AL10="Pelo ponto",$AK10="",$E10="",$X10="Sim"),"PONTO: sem ponto nem horas manuais — descontando jornada cheia",IF(AND($AL10="Leve atraso",$E10="",N($AO10)>P_LeveMax),"CLASSIFICAR: ponto mostra atraso > 30 min — trocar o Status",IF($AF10="Leve atraso","AJUSTAR STATUS: atraso lançado como Horas Trabalhadas",IF(AND(N($K10)>0,$G10=""),"OBSERVAÇÃO: desconto extra sem observação",IF(AND($J10<>"",N($K10)+N($L10)>$U10),"CONFERIR: horas manuais maiores que a jornada",""))))))))))))) | AJ10: =IF(OR($A10="",$O10="",$O10="?"),"",IFERROR(MATCH($O10&"|"&SUMPRODUCT(MAX((V_RG=$O10)*(V_Ini<=$A10)*V_Ini)),V_Chave,0),"")) | AK10: =IF(ISNUMBER(SEARCH(" = ",$D10)),IFERROR(TIMEVALUE(TRIM(RIGHT($D10,5))),""),"") | AL10: =IF($C10="","",IFERROR(INDEX(S_Modo,MATCH($C10,S_Status,0)),"Não")) -> Dia inteiro | AM10: =IF($C10="","",IFERROR(INDEX(S_Conta,MATCH($C10,S_Status,0)),"Não")) -> Sim | AN10: =IF($C10="","",IFERROR(INDEX(S_Trab,MATCH($C10,S_Status,0)),"Não")) -> Não | AO10: =IF(OR($A10="",$AK10=""),"",$U10-$AK10-IF($J10<>"Situação Atípica - Presente",N($K10)+N($L10),0)) | AP10: =IF(OR($A10="",TRIM($B10)=""),"",TRIM($B10)&"|"&$A10) | AQ10: =IF(AND(P_CoberturaAuto="Sim",$A10<>"",$A10>=P_InicioRegras,$Q10="Normal / Fixo",$R10<>"",ISERROR(SEARCH("ENCARREGADO",$R10)),$AM10="Sim",$W10>0),$A10&"|"&$P10,"") | AR10: =IF($AQ10="","",COUNTIFS(L_ChaveCob,$AQ10,L_Ausencia,">"&$W10)+COUNTIFS($AQ$4:$AQ10,$AQ10,$W$4:$W10,$W10)) | AS10: =IF($AQ10="",0,SUMIFS(L_Trab,L_Data,$A10,L_Equipe,$P10,L_Contrato,"Ferista",L_Status,"<>Remanejamento")) -> 0 | AT10: =IF(OR($AQ10="",$AS10=0),0,MAX(MIN($W10,$AS10-SUMIFS(L_Ausencia,L_ChaveCob,$AQ10,L_OrdemCob,"<"&$AR10)),0)) -> 0 | AU10: =IF($AP10="",0,SUMIFS(CP_Horas,CP_ChaveFalta,$AP10,CP_Aprov,"<>Sim")) -> 0
